[I 06:40:58.275 NotebookApp] The port 8888 is already in use, trying another port.
[I 06:40:58.275 NotebookApp] The port 8889 is already in use, trying another port.
[I 06:40:58.276 NotebookApp] Serving notebooks from local directory: /Users/sigbjobo/research/clusters/expanse/research_storage/ice_liquid_interface/TIP4P_ICE/IceIII_Liquid/4-PrepareCoexistenceConfiguration
[I 06:40:58.276 NotebookApp] Jupyter Notebook 6.4.4 is running at:
[I 06:40:58.276 NotebookApp] http://localhost:8890/?token=806bb3c23fe53c583fdd5abdcfc72ae277985292aaa791d8
[I 06:40:58.276 NotebookApp]  or http://127.0.0.1:8890/?token=806bb3c23fe53c583fdd5abdcfc72ae277985292aaa791d8
[I 06:40:58.276 NotebookApp] Use Control-C to stop this server and shut down all kernels (twice to skip confirmation).
[C 06:40:58.279 NotebookApp] 
    
    To access the notebook, open this file in a browser:
        file:///Users/sigbjobo/Library/Jupyter/runtime/nbserver-7034-open.html
    Or copy and paste one of these URLs:
        http://localhost:8890/?token=806bb3c23fe53c583fdd5abdcfc72ae277985292aaa791d8
     or http://127.0.0.1:8890/?token=806bb3c23fe53c583fdd5abdcfc72ae277985292aaa791d8
/Users/sigbjobo/miniforge3/lib/python3.9/json/encoder.py:257: UserWarning: date_default is deprecated since jupyter_client 7.0.0. Use jupyter_client.jsonutil.json_default.
  return _iterencode(o, 0)
ERROR:asyncio:Exception in callback <TaskWakeupMethWrapper object at 0x105a9ec40>(<Future finis...719"\r\n\r\n'>)
handle: <Handle <TaskWakeupMethWrapper object at 0x105a9ec40>(<Future finis...719"\r\n\r\n'>)>
Traceback (most recent call last):
  File "/Users/sigbjobo/miniforge3/lib/python3.9/asyncio/events.py", line 80, in _run
    self._context.run(self._callback, *self._args)
RuntimeError: Cannot enter into task <Task pending name='Task-8' coro=<HTTP1ServerConnection._server_request_loop() running at /Users/sigbjobo/miniforge3/lib/python3.9/site-packages/tornado/http1connection.py:823> wait_for=<Future finished result=b'GET /api/co...2719"\r\n\r\n'> cb=[IOLoop.add_future.<locals>.<lambda>() at /Users/sigbjobo/miniforge3/lib/python3.9/site-packages/tornado/ioloop.py:688]> while another task <Task pending name='Task-1' coro=<MultiKernelManager._async_start_kernel() running at /Users/sigbjobo/miniforge3/lib/python3.9/site-packages/jupyter_client/multikernelmanager.py:186>> is being executed.
ERROR:asyncio:Exception in callback <TaskWakeupMethWrapper object at 0x105a9ea60>(<Future finis...719"\r\n\r\n'>)
handle: <Handle <TaskWakeupMethWrapper object at 0x105a9ea60>(<Future finis...719"\r\n\r\n'>)>
Traceback (most recent call last):
  File "/Users/sigbjobo/miniforge3/lib/python3.9/asyncio/events.py", line 80, in _run
    self._context.run(self._callback, *self._args)
RuntimeError: Cannot enter into task <Task pending name='Task-1' coro=<HTTP1ServerConnection._server_request_loop() running at /Users/sigbjobo/miniforge3/lib/python3.9/site-packages/tornado/http1connection.py:823> wait_for=<Future finished result=b'GET /kernel...2719"\r\n\r\n'> cb=[IOLoop.add_future.<locals>.<lambda>() at /Users/sigbjobo/miniforge3/lib/python3.9/site-packages/tornado/ioloop.py:688]> while another task <Task pending name='Task-2' coro=<KernelManager._async_start_kernel() running at /Users/sigbjobo/miniforge3/lib/python3.9/site-packages/jupyter_client/manager.py:332>> is being executed.
[I 06:41:04.843 NotebookApp] Kernel started: 6757bb6d-722a-441c-993d-238163413735, name: python3
/Users/sigbjobo/miniforge3/lib/python3.9/json/encoder.py:257: UserWarning: date_default is deprecated since jupyter_client 7.0.0. Use jupyter_client.jsonutil.json_default.
  return _iterencode(o, 0)
[I 06:51:04.920 NotebookApp] Saving file at /Prepare_coexsistence.ipynb
[I 07:05:04.788 NotebookApp] Saving file at /Prepare_coexsistence.ipynb
[I 07:07:04.868 NotebookApp] Saving file at /Prepare_coexsistence.ipynb
[I 07:11:05.668 NotebookApp] Saving file at /Prepare_coexsistence.ipynb
[I 08:39:09.571 NotebookApp] Starting buffering for 6757bb6d-722a-441c-993d-238163413735:623e23b865c44f318c0ba8c17d58809c
